{
 "cells": [
  {
   "cell_type": "code",
   "execution_count": 31,
   "metadata": {},
   "outputs": [],
   "source": [
    "import numpy as np\n",
    "from tensorflow.keras.preprocessing.image import load_img\n",
    "from tensorflow.keras.utils import img_to_array\n",
    "from keras.models import load_model\n",
    "from tensorflow.keras.applications.resnet50 import preprocess_input"
   ]
  },
  {
   "cell_type": "code",
   "execution_count": 32,
   "metadata": {},
   "outputs": [],
   "source": [
    "model = load_model(\"mymodel.h5\")"
   ]
  },
  {
   "cell_type": "code",
   "execution_count": 34,
   "metadata": {},
   "outputs": [],
   "source": [
    "img = load_img(\"211.jpg\", target_size=(224,224))\n",
    "x = img_to_array(img)\n",
    "x = np.expand_dims(x, axis=0)\n",
    "x = preprocess_input(x)"
   ]
  },
  {
   "cell_type": "code",
   "execution_count": 35,
   "metadata": {},
   "outputs": [
    {
     "ename": "ValueError",
     "evalue": "in user code:\n\n    File \"c:\\Users\\Ashish Kalra\\anaconda3\\lib\\site-packages\\keras\\engine\\training.py\", line 2041, in predict_function  *\n        return step_function(self, iterator)\n    File \"c:\\Users\\Ashish Kalra\\anaconda3\\lib\\site-packages\\keras\\engine\\training.py\", line 2027, in step_function  **\n        outputs = model.distribute_strategy.run(run_step, args=(data,))\n    File \"c:\\Users\\Ashish Kalra\\anaconda3\\lib\\site-packages\\keras\\engine\\training.py\", line 2015, in run_step  **\n        outputs = model.predict_step(data)\n    File \"c:\\Users\\Ashish Kalra\\anaconda3\\lib\\site-packages\\keras\\engine\\training.py\", line 1983, in predict_step\n        return self(x, training=False)\n    File \"c:\\Users\\Ashish Kalra\\anaconda3\\lib\\site-packages\\keras\\utils\\traceback_utils.py\", line 70, in error_handler\n        raise e.with_traceback(filtered_tb) from None\n    File \"c:\\Users\\Ashish Kalra\\anaconda3\\lib\\site-packages\\keras\\engine\\input_spec.py\", line 295, in assert_input_compatibility\n        raise ValueError(\n\n    ValueError: Input 0 of layer \"sequential\" is incompatible with the layer: expected shape=(None, 25088), found shape=(None, 224, 224, 3)\n",
     "output_type": "error",
     "traceback": [
      "\u001b[1;31m---------------------------------------------------------------------------\u001b[0m",
      "\u001b[1;31mValueError\u001b[0m                                Traceback (most recent call last)",
      "\u001b[1;32mC:\\Users\\ASHISH~1\\AppData\\Local\\Temp/ipykernel_3348/55869425.py\u001b[0m in \u001b[0;36m<module>\u001b[1;34m\u001b[0m\n\u001b[1;32m----> 1\u001b[1;33m \u001b[0mpredictions\u001b[0m \u001b[1;33m=\u001b[0m \u001b[0mmodel\u001b[0m\u001b[1;33m.\u001b[0m\u001b[0mpredict\u001b[0m\u001b[1;33m(\u001b[0m\u001b[0mx\u001b[0m\u001b[1;33m)\u001b[0m\u001b[1;33m\u001b[0m\u001b[1;33m\u001b[0m\u001b[0m\n\u001b[0m",
      "\u001b[1;32mc:\\Users\\Ashish Kalra\\anaconda3\\lib\\site-packages\\keras\\utils\\traceback_utils.py\u001b[0m in \u001b[0;36merror_handler\u001b[1;34m(*args, **kwargs)\u001b[0m\n\u001b[0;32m     68\u001b[0m             \u001b[1;31m# To get the full stack trace, call:\u001b[0m\u001b[1;33m\u001b[0m\u001b[1;33m\u001b[0m\u001b[0m\n\u001b[0;32m     69\u001b[0m             \u001b[1;31m# `tf.debugging.disable_traceback_filtering()`\u001b[0m\u001b[1;33m\u001b[0m\u001b[1;33m\u001b[0m\u001b[0m\n\u001b[1;32m---> 70\u001b[1;33m             \u001b[1;32mraise\u001b[0m \u001b[0me\u001b[0m\u001b[1;33m.\u001b[0m\u001b[0mwith_traceback\u001b[0m\u001b[1;33m(\u001b[0m\u001b[0mfiltered_tb\u001b[0m\u001b[1;33m)\u001b[0m \u001b[1;32mfrom\u001b[0m \u001b[1;32mNone\u001b[0m\u001b[1;33m\u001b[0m\u001b[1;33m\u001b[0m\u001b[0m\n\u001b[0m\u001b[0;32m     71\u001b[0m         \u001b[1;32mfinally\u001b[0m\u001b[1;33m:\u001b[0m\u001b[1;33m\u001b[0m\u001b[1;33m\u001b[0m\u001b[0m\n\u001b[0;32m     72\u001b[0m             \u001b[1;32mdel\u001b[0m \u001b[0mfiltered_tb\u001b[0m\u001b[1;33m\u001b[0m\u001b[1;33m\u001b[0m\u001b[0m\n",
      "\u001b[1;32mc:\\Users\\Ashish Kalra\\anaconda3\\lib\\site-packages\\keras\\engine\\training.py\u001b[0m in \u001b[0;36mtf__predict_function\u001b[1;34m(iterator)\u001b[0m\n\u001b[0;32m     13\u001b[0m                 \u001b[1;32mtry\u001b[0m\u001b[1;33m:\u001b[0m\u001b[1;33m\u001b[0m\u001b[1;33m\u001b[0m\u001b[0m\n\u001b[0;32m     14\u001b[0m                     \u001b[0mdo_return\u001b[0m \u001b[1;33m=\u001b[0m \u001b[1;32mTrue\u001b[0m\u001b[1;33m\u001b[0m\u001b[1;33m\u001b[0m\u001b[0m\n\u001b[1;32m---> 15\u001b[1;33m                     \u001b[0mretval_\u001b[0m \u001b[1;33m=\u001b[0m \u001b[0mag__\u001b[0m\u001b[1;33m.\u001b[0m\u001b[0mconverted_call\u001b[0m\u001b[1;33m(\u001b[0m\u001b[0mag__\u001b[0m\u001b[1;33m.\u001b[0m\u001b[0mld\u001b[0m\u001b[1;33m(\u001b[0m\u001b[0mstep_function\u001b[0m\u001b[1;33m)\u001b[0m\u001b[1;33m,\u001b[0m \u001b[1;33m(\u001b[0m\u001b[0mag__\u001b[0m\u001b[1;33m.\u001b[0m\u001b[0mld\u001b[0m\u001b[1;33m(\u001b[0m\u001b[0mself\u001b[0m\u001b[1;33m)\u001b[0m\u001b[1;33m,\u001b[0m \u001b[0mag__\u001b[0m\u001b[1;33m.\u001b[0m\u001b[0mld\u001b[0m\u001b[1;33m(\u001b[0m\u001b[0miterator\u001b[0m\u001b[1;33m)\u001b[0m\u001b[1;33m)\u001b[0m\u001b[1;33m,\u001b[0m \u001b[1;32mNone\u001b[0m\u001b[1;33m,\u001b[0m \u001b[0mfscope\u001b[0m\u001b[1;33m)\u001b[0m\u001b[1;33m\u001b[0m\u001b[1;33m\u001b[0m\u001b[0m\n\u001b[0m\u001b[0;32m     16\u001b[0m                 \u001b[1;32mexcept\u001b[0m\u001b[1;33m:\u001b[0m\u001b[1;33m\u001b[0m\u001b[1;33m\u001b[0m\u001b[0m\n\u001b[0;32m     17\u001b[0m                     \u001b[0mdo_return\u001b[0m \u001b[1;33m=\u001b[0m \u001b[1;32mFalse\u001b[0m\u001b[1;33m\u001b[0m\u001b[1;33m\u001b[0m\u001b[0m\n",
      "\u001b[1;31mValueError\u001b[0m: in user code:\n\n    File \"c:\\Users\\Ashish Kalra\\anaconda3\\lib\\site-packages\\keras\\engine\\training.py\", line 2041, in predict_function  *\n        return step_function(self, iterator)\n    File \"c:\\Users\\Ashish Kalra\\anaconda3\\lib\\site-packages\\keras\\engine\\training.py\", line 2027, in step_function  **\n        outputs = model.distribute_strategy.run(run_step, args=(data,))\n    File \"c:\\Users\\Ashish Kalra\\anaconda3\\lib\\site-packages\\keras\\engine\\training.py\", line 2015, in run_step  **\n        outputs = model.predict_step(data)\n    File \"c:\\Users\\Ashish Kalra\\anaconda3\\lib\\site-packages\\keras\\engine\\training.py\", line 1983, in predict_step\n        return self(x, training=False)\n    File \"c:\\Users\\Ashish Kalra\\anaconda3\\lib\\site-packages\\keras\\utils\\traceback_utils.py\", line 70, in error_handler\n        raise e.with_traceback(filtered_tb) from None\n    File \"c:\\Users\\Ashish Kalra\\anaconda3\\lib\\site-packages\\keras\\engine\\input_spec.py\", line 295, in assert_input_compatibility\n        raise ValueError(\n\n    ValueError: Input 0 of layer \"sequential\" is incompatible with the layer: expected shape=(None, 25088), found shape=(None, 224, 224, 3)\n"
     ]
    }
   ],
   "source": [
    "predictions = model.predict(x)"
   ]
  }
 ],
 "metadata": {
  "kernelspec": {
   "display_name": "base",
   "language": "python",
   "name": "python3"
  },
  "language_info": {
   "codemirror_mode": {
    "name": "ipython",
    "version": 3
   },
   "file_extension": ".py",
   "mimetype": "text/x-python",
   "name": "python",
   "nbconvert_exporter": "python",
   "pygments_lexer": "ipython3",
   "version": "3.9.7"
  },
  "orig_nbformat": 4
 },
 "nbformat": 4,
 "nbformat_minor": 2
}
